<?xml version="1.0" encoding="utf-8"?>
<!-- This URDF was automatically created by SolidWorks to URDF Exporter! Originally created by Stephen Brawner (brawner@gmail.com) 
     Commit Version: 1.6.0-4-g7f85cfe  Build Version: 1.6.7995.38578
     For more information, please see http://wiki.ros.org/sw_urdf_exporter -->
<robot
  name="robot">
  <link
    name="base_link">
    <inertial>
      <origin
        xyz="0.28868742442495 1.44805433774299 -0.0402233450418269"
        rpy="0 0 0" />
      <mass
        value="23.3878159132999" />
      <inertia
        ixx="6.42514922450971"
        ixy="-2.19749690377613E-16"
        ixz="1.02478845664697E-16"
        iyy="1.98700916020424"
        iyz="5.62265918604536E-10"
        izz="4.4441181284017" />
    </inertial>
    <visual>
      <origin
        xyz="0 0 0"
        rpy="0 0 0" />
      <geometry>
        <mesh
          filename="package://robot/meshes/base_link.STL" />
      </geometry>
      <material
        name="">
        <color
          rgba="1 1 1 1" />
      </material>
    </visual>
    <collision>
      <origin
        xyz="0 0 0"
        rpy="0 0 0" />
      <geometry>
        <mesh
          filename="package://robot/meshes/base_link.STL" />
      </geometry>
    </collision>
  </link>
  <link
    name="v">
    <inertial>
      <origin
        xyz="0.0337455704948449 -0.00999999999999988 0"
        rpy="0 0 0" />
      <mass
        value="9.20530737736013" />
      <inertia
        ixx="0.470911965660408"
        ixy="-9.67307589726037E-19"
        ixz="2.84975407375212E-19"
        iyy="0.0122067836321299"
        iyz="-7.38989331731531E-17"
        izz="0.466973961489154" />
    </inertial>
    <visual>
      <origin
        xyz="0 0 0"
        rpy="0 0 0" />
      <geometry>
        <mesh
          filename="package://robot/meshes/v.STL" />
      </geometry>
      <material
        name="">
        <color
          rgba="1 1 1 1" />
      </material>
    </visual>
    <collision>
      <origin
        xyz="0 0 0"
        rpy="0 0 0" />
      <geometry>
        <mesh
          filename="package://robot/meshes/v.STL" />
      </geometry>
    </collision>
  </link>
  <joint
    name="v"
    type="fixed">
    <origin
      xyz="0.314391039627408 1.44805433774299 -0.0302233450418268"
      rpy="1.5707963267949 0 0" />
    <parent
      link="base_link" />
    <child
      link="v" />
    <axis
      xyz="0 0 0" />
  </joint>
  <link
    name="h">
    <inertial>
      <origin
        xyz="0.430000000000001 0.00104386561702341 0.0250000000001606"
        rpy="0 0 0" />
      <mass
        value="1.20404538970621" />
      <inertia
        ixx="0.000392533091920462"
        ixy="4.69217332462954E-18"
        ixz="1.27363876203556E-08"
        iyy="0.172653021241885"
        iyz="-2.22720298348333E-19"
        izz="0.172649729074278" />
    </inertial>
    <visual>
      <origin
        xyz="0 0 0"
        rpy="0 0 0" />
      <geometry>
        <mesh
          filename="package://robot/meshes/h.STL" />
      </geometry>
      <material
        name="">
        <color
          rgba="1 1 1 1" />
      </material>
    </visual>
    <collision>
      <origin
        xyz="0 0 0"
        rpy="0 0 0" />
      <geometry>
        <mesh
          filename="package://robot/meshes/h.STL" />
      </geometry>
    </collision>
  </link>
  <joint
    name="h"
    type="prismatic">
    <origin
      xyz="0.0624999999999986 -0.0462005689729977 0.43"
      rpy="1.5707963267949 1.5707963267949 0" />
    <parent
      link="v" />
    <child
      link="h" />
    <axis
      xyz="0 0 1" />
    <limit
      lower="-0.3202"
      upper="0.2278"
      effort="0"
      velocity="0" />
  </joint>
  <link
    name="base">
    <inertial>
      <origin
        xyz="0.0299999999999998 0.005462962962963 -0.00201846884051221"
        rpy="0 0 0" />
      <mass
        value="0.122887911388917" />
      <inertia
        ixx="8.08558410388411E-05"
        ixy="-5.38824986379029E-13"
        ixz="-9.25019774243767E-20"
        iyy="7.28213386278354E-05"
        iyz="3.21829894470866E-20"
        izz="7.17038365501508E-05" />
    </inertial>
    <visual>
      <origin
        xyz="0 0 0"
        rpy="0 0 0" />
      <geometry>
        <mesh
          filename="package://robot/meshes/base.STL" />
      </geometry>
      <material
        name="">
        <color
          rgba="1 1 1 1" />
      </material>
    </visual>
    <collision>
      <origin
        xyz="0 0 0"
        rpy="0 0 0" />
      <geometry>
        <mesh
          filename="package://robot/meshes/base.STL" />
      </geometry>
    </collision>
  </link>
  <joint
    name="b"
    type="prismatic">
    <origin
      xyz="0.786693625190159 0.0090740740740754 0.0304629629631233"
      rpy="-1.5707963267949 0 0" />
    <parent
      link="h" />
    <child
      link="base" />
    <axis
      xyz="1 0 0" />
    <limit
      lower="-0.88669"
      upper="0.012306"
      effort="0"
      velocity="0" />
  </joint>
  <link
    name="p1">
    <inertial>
      <origin
        xyz="-0.251043490081928 -0.000464975447103555 1.45508950444295E-08"
        rpy="0 0 0" />
      <mass
        value="1.13971656121822" />
      <inertia
        ixx="0.000432514158950848"
        ixy="-2.96751620309246E-05"
        ixz="3.48820471697827E-09"
        iyy="0.0298367965148194"
        iyz="-1.09120578328445E-09"
        izz="0.0299694646418855" />
    </inertial>
    <visual>
      <origin
        xyz="0 0 0"
        rpy="0 0 0" />
      <geometry>
        <mesh
          filename="package://robot/meshes/p1.STL" />
      </geometry>
      <material
        name="">
        <color
          rgba="1 1 1 1" />
      </material>
    </visual>
    <collision>
      <origin
        xyz="0 0 0"
        rpy="0 0 0" />
      <geometry>
        <mesh
          filename="package://robot/meshes/p1.STL" />
      </geometry>
    </collision>
  </link>
  <joint
    name="p1"
    type="continuous">
    <origin
      xyz="0.0300000000000005 0.00546296296296789 0.0159259259259247"
      rpy="1.69844635565354 1.5707963267949 0" />
    <parent
      link="base" />
    <child
      link="p1" />
    <axis
      xyz="1 0 0" />
  </joint>
  <link
    name="p2">
    <inertial>
      <origin
        xyz="-4.71844785465692E-15 -1.65423230669148E-14 0.221715000000003"
        rpy="0 0 0" />
      <mass
        value="0.580514506690596" />
      <inertia
        ixx="0.0125224058122683"
        ixy="-2.16840434497101E-19"
        ixz="-5.60159828678214E-17"
        iyy="0.012506656553382"
        iyz="-6.067466407772E-17"
        izz="0.000275346295122351" />
    </inertial>
    <visual>
      <origin
        xyz="0 0 0"
        rpy="0 0 0" />
      <geometry>
        <mesh
          filename="package://robot/meshes/p2.STL" />
      </geometry>
      <material
        name="">
        <color
          rgba="1 1 1 1" />
      </material>
    </visual>
    <collision>
      <origin
        xyz="0 0 0"
        rpy="0 0 0" />
      <geometry>
        <mesh
          filename="package://robot/meshes/p2.STL" />
      </geometry>
    </collision>
  </link>
  <joint
    name="p2"
    type="revolute">
    <origin
      xyz="-0.568084800154274 0 0"
      rpy="-2.88843035194422 -1.57079630572147 -2.06988390055919" />
    <parent
      link="p1" />
    <child
      link="p2" />
    <axis
      xyz="1 0 0" />
    <limit
      lower="-4.0944"
      upper="1.4906"
      effort="0"
      velocity="0" />
  </joint>
  <link
    name="p3">
    <inertial>
      <origin
        xyz="-0.221710271897552 0.00144795031442091 -5.77315972805081E-15"
        rpy="0 0 0" />
      <mass
        value="0.523965838925978" />
      <inertia
        ixx="0.000160235547863617"
        ixy="6.17235408899563E-05"
        ixz="1.31696682639099E-17"
        iyy="0.00961094612835153"
        iyz="1.89735380184963E-19"
        izz="0.00973625062028675" />
    </inertial>
    <visual>
      <origin
        xyz="0 0 0"
        rpy="0 0 0" />
      <geometry>
        <mesh
          filename="package://robot/meshes/p3.STL" />
      </geometry>
      <material
        name="">
        <color
          rgba="1 1 1 1" />
      </material>
    </visual>
    <collision>
      <origin
        xyz="0 0 0"
        rpy="0 0 0" />
      <geometry>
        <mesh
          filename="package://robot/meshes/p3.STL" />
      </geometry>
    </collision>
  </link>
  <joint
    name="p3"
    type="revolute">
    <origin
      xyz="0 0 0.443430000000003"
      rpy="1.57079632679621 1.56753096223434 1.57079632679621" />
    <parent
      link="p2" />
    <child
      link="p3" />
    <axis
      xyz="0 0 1" />
    <limit
      lower="-2.78926143863038"
      upper="2.79579216775148"
      effort="0"
      velocity="0" />
  </joint>
  <link
    name="p4">
    <inertial>
      <origin
        xyz="5.49560397189452E-15 0.0871661241402411 -0.0372480271176578"
        rpy="0 0 0" />
      <mass
        value="0.583844311345297" />
      <inertia
        ixx="0.00244029530315811"
        ixy="2.39879730662418E-18"
        ixz="-1.84314369322536E-18"
        iyy="0.00147441209728121"
        iyz="0.000565725026276999"
        izz="0.00113021131852825" />
    </inertial>
    <visual>
      <origin
        xyz="0 0 0"
        rpy="0 0 0" />
      <geometry>
        <mesh
          filename="package://robot/meshes/p4.STL" />
      </geometry>
      <material
        name="">
        <color
          rgba="1 1 1 1" />
      </material>
    </visual>
    <collision>
      <origin
        xyz="0 0 0"
        rpy="0 0 0" />
      <geometry>
        <mesh
          filename="package://robot/meshes/p4.STL" />
      </geometry>
    </collision>
  </link>
  <joint
    name="p4"
    type="continuous">
    <origin
      xyz="-0.443420543795106 0.00289590062884193 0"
      rpy="-2.21293240401649 1.57079631189374 -0.408206025430802" />
    <parent
      link="p3" />
    <child
      link="p4" />
    <axis
      xyz="1 0 0" />
    <limit
      lower="-2"
      upper="2"
      effort="0"
      velocity="0" />
  </joint>
</robot>